<?xml version="1.0"?>
<robot name="dd_model">
    
    <gazebo>
        <plugin name="gazebo_ros_control" filename="libgazebo_ros_control.so">
            <robotNamespace>/</robotNamespace>
        </plugin>
    </gazebo>
    
   <material name="red">
        <color rgba="0 1 0.8 1"/>
    </material>  
    
    <material name="blue">
        <color rgba="1 0 0.8 1"/>
    </material> 
    
  <link name="base_link">
    <visual>
      <geometry>
        <box size="1 0.5 0.1"/>
      </geometry>
      <material name="blue"/>
    </visual>
    <inertial>
        <mass value="5" />
        <inertia ixx="0.04" ixy="0.0" ixz="0.0" iyy="0.04" iyz="0.0" izz="0.02"/>
    </inertial>
    <collision>
      <geometry>
        <box size="1 0.2 0.1" />
      </geometry>
      <contact_coefficients>
          <mu value="0.0001" />
          <kp value="10000000.0" />
          <kd value="1.0" />
      </contact_coefficients>    
    </collision>
  </link>

  <link name="wheel1">
    <visual>
      <geometry>
        <cylinder radius="0.2" length="0.2"/>
      </geometry>
      <material name="red"/>
    </visual>
    <inertial>
        <mass value="1" />
        <inertia ixx="0.04" ixy="0.0" ixz="0.0" iyy="0.04" iyz="0.0" izz="0.02"/>
    </inertial>
    <collision>
      <geometry>
        <cylinder radius="0.2" length="0.2" />
      </geometry>
        </collision>
  </link>
  
  <link name="wheel2">
    <visual>
      <geometry>
        <cylinder radius="0.2" length="0.2"/>
      </geometry>
      <material name="red"/>
    </visual>
    <inertial>
        <mass value="1" />
        <inertia ixx="0.04" ixy="0.0" ixz="0.0" iyy="0.04" iyz="0.0" izz="0.02"/>
    </inertial>
    <collision>
      <geometry>
        <cylinder radius="0.2" length="0.2" />
      </geometry>
        </collision>
  </link>
  
  <link name="support">
    <visual>
      <geometry>
        <sphere radius="0.1"/>
      </geometry>
      <material name="red"/>
    </visual>
    <inertial>
        <mass value="1" />
        <inertia ixx="0.04" ixy="0.0" ixz="0.0" iyy="0.04" iyz="0.0" izz="0.02"/>
    </inertial>
    <collision>
      <geometry>
        <sphere radius="0.1"/>
      </geometry>
      <contact_coefficients>
          <mu value="0.000001" />
          <kp value="10000000.0" />
          <kd value="1.0" />
      </contact_coefficients>
        </collision>
  </link>

  <joint name="base_to_wheel1" type="continuous">
    <axis rpy="0 0 0" xyz="0 0 1"/>
    <parent link="base_link"/>
    <child link="wheel1"/>
    <origin rpy="1.57 0 0" xyz="0.5 -0.25 0"/>
    <limit effort="5000" velocity="10.0"/>
  </joint>
  
  <joint name="base_to_wheel2" type="continuous">
    <axis rpy="0 0 0" xyz="0 0 1"/>
    <parent link="base_link"/>
    <child link="wheel2"/>
    <origin rpy="1.57 0 0" xyz="0.5 0.25 0"/>
    <limit effort="5000" velocity="10.0"/>
  </joint>
  
  <joint name="base_to_support" type="fixed">
    <axis rpy="0 0 0" xyz="0 0 1"/>
    <parent link="base_link"/>
    <child link="support"/>
    <origin xyz="-0.4 0 -0.1"/>
  </joint>
  
  <transmission name="wheel1_tr">
    <type> transmission_interface/SimpleTransmission </type>
        <actuator name="motor1">
            <mechanicalReduction>1</mechanicalReduction>
        </actuator>
    <joint name="base_to_wheel1">
      <hardwareInterface>hardware_interface/VelocityJointInterface</hardwareInterface>
    </joint>
  </transmission>  
  
  <transmission name="wheel2_tr">
    <type> transmission_interface/SimpleTransmission </type>
        <actuator name="motor1">
            <mechanicalReduction>1</mechanicalReduction>
     </actuator>
    <joint name="base_to_wheel2">
      <hardwareInterface>hardware_interface/VelocityJointInterface</hardwareInterface>
    </joint>
  </transmission>  

  
  <gazebo reference="wheel1">
    <mu1 value="200.0"/>
    <mu2 value="100.0"/>
    <kp value="10000000.0" />
    <kd value="1.0" />
    <material>Gazebo/Grey</material>
  </gazebo>
  
  <gazebo reference="support">
    <mu1 value="0.00001"/>
    <mu2 value="0.00001"/>
    <kp value="10000000.0" />
    <kd value="1.0" />
    <material>Gazebo/Grey</material>
  </gazebo>
  
  <gazebo reference="wheel2">
    <mu1 value="200.0"/>
    <mu2 value="100.0"/>
    <kp value="10000000.0" />
    <kd value="1.0" />
    <material>Gazebo/Grey</material>
  </gazebo>
  
</robot>
